Workbook

Sheet UpdateSheet
A1: Agent Name | B1: Location | D1: Product | G1: Date | H1: Product_Name | I1: Quantity | J1: Offer | K1: Sales_Price | L1: Unit_Cost | M1: Product | N1: Quantity | O1: Sales_Price | P1: Unit_Cost | U1: Date | V1: Product_Name | W1: Unit_Cost | X1: CRS | Y1: Product | Z1: Supplier
A2: Fomax | B2: Abuja | D2: Babatunde@01$ | G2: 45768 | H2: Vacuum Sealer | I2: 1 | J2: 0 | K2: 35500 | L2: 9000 | U2: 45839 | V2: Vacuum Sealer | W2: 9500 | X2: Nuella | Y2: All
A3: HS_Logistics | B3: Anambra | D3: Nylon | G3: 45768 | H3: Vacuum Sealer | I3: 2 | J3: 0 | K3: 49500 | L3: 9000 | U3: 45839 | V3: Nylon | W3: 150 | X3: CRS1 | Y3: {=D2:D976} -> Babatunde@01$
A4: Oluwadunsin | B4: Ekiti | D4: Smart Tablet | G4: 45768 | H4: Vacuum Sealer | I4: 3 | J4: 0 | K4: 61500 | L4: 9000 | U4: 45839 | V4: Smart Tablet | W4: 12000 | Y4: Nylon
A5: Peng_Logistics | B5: Bayelsa | G5: 45803 | H5: Vacuum Sealer | I5: 4 | J5: 0 | K5: 82500 | L5: 9500 | Y5: Smart Tablet
A6: Chidera_Logistics | B6: Delta | G6: 45803 | H6: Vacuum Sealer | I6: 1 | J6: 0 | K6: 35500 | L6: 9500 | M6: Nylon | N6: 50 | O6: 30500 | P6: 100
A7: Kings_Store | B7: Delta | G7: 45803 | H7: Vacuum Sealer | I7: 2 | J7: 0 | K7: 49500 | L7: 9500 | M7: Nylon | N7: 100 | O7: 51500 | P7: 100
A8: Adebayo | B8: Ondo | G8: 45803 | H8: Vacuum Sealer | I8: 3 | J8: 0 | K8: 61500 | L8: 9500 | M8: Nylon | N8: 200 | O8: 84500 | P8: 100
A9: Samsucc Logistics | B9: Auchi | G9: 45870 | H9: Smart Tablet | I9: 1 | J9: 0 | K9: 41500 | L9: 12000
A10: Quickwaka | B10: Abakaliki | G10: 45870 | H10: Smart Tablet | I10: 2 | J10: 0 | K10: 65500 | L10: 12000
A11: Eclipse Logistics | B11: Ibadan Osun | G11: 45870 | H11: Smart Tablet | I11: 3 | J11: 0 | K11: 113500 | L11: 12000
A12: Sagok Logistics | B12: Port-harcourt | G12: 45870 | H12: Smart Tablet | I12: 4 | J12: 0 | K12: 135000 | L12: 12000
A13: Soshine | B13: Ogun/Abeokuta | G13: 45877 | H13: Vacuum Sealer | I13: 1 | J13: 0 | K13: 35500 | L13: 9500 | M13: Nylon | N13: 50 | O13: 30500 | P13: 150
A14: Gologistics (Uyo) | B14: Uyo/Calabar | G14: 45877 | H14: Vacuum Sealer | I14: 2 | J14: 0 | K14: 49500 | L14: 9500 | M14: Nylon | N14: 100 | O14: 51500 | P14: 150
A15: Gologistics (Calabar) | B15: Calabar | G15: 45877 | H15: Vacuum Sealer | I15: 3 | J15: 0 | K15: 61500 | L15: 9500 | M15: Nylon | N15: 200 | O15: 84500 | P15: 150
A16: Delvit (Enugu) | B16: Enugu | G16: 45877 | H16: Vacuum Sealer | I16: 4 | J16: 0 | K16: 82500 | L16: 9500
A17: Vikaad (Nasarawa) | B17: Nasarawa
A18: Vikaad (Kano) | B18: Kano
A19: Drop goods _Logistics | B19: Imo
A20: Aba logistics | B20: Aba/Abia
A21: Formax (Rivers) | B21: Rivers State
A22: Azird | B22: Delta
A23: MBC LOGISTICS | B23: All northern state
A24: Isioma Lagos agent
A25: Aboyeji | B25: Lagos
A26: KK Logistics | B26: Kwara
A27: Mr Toheeb
A28: Kings Errand Logistics | B28: Anambra
A29: plateau online | B29: North

Sheet Product
A1: Date | B1: Month | C1: Description | D1: Waybilled | E1: Delivered | F1: Total | I1: Month | J1: Waybilled | K1: Delivered | L1: BALANCE
A2: 45900 | B2: =if(A2="","",TEXT(A2,"MMMM")) -> August | C2: VS | D2: 1185750 | E2: 682000 | F2: =if(A2="","",D2-E2) -> 503750 | I2: January | J2: =SUMIF($B:$B,$I2,D:D) -> 0 | K2: =SUMIF($B:$B,$I2,E:E) -> 0 | L2: =J2-K2 -> 0
A3: 45900 | B3: =if(A3="","",TEXT(A3,"MMMM")) -> August | C3: EED | D3: 976000 | E3: 132000 | F3: =if(A3="","",F2+D3-E3) -> 1347750 | I3: February | J3: =SUMIF($B:$B,$I3,D:D) -> 0 | K3: =SUMIF($B:$B,$I3,E:E) -> 0 | L3: =J3-K3 -> 0
A4: 45930 | B4: =if(A4="","",TEXT(A4,"MMMM")) -> September | C4: VS | D4: 1053000 | E4: 1304000 | F4: =if(A4="","",F3+D4-E4) -> 1096750 | I4: March | J4: =SUMIF($B:$B,$I4,D:D) -> 0 | K4: =SUMIF($B:$B,$I4,E:E) -> 0 | L4: =J4-K4 -> 0
B5: =if(A5="","",TEXT(A5,"MMMM")) | F5: =if(A5="","",F4+D5-E5) | I5: April | J5: =SUMIF($B:$B,$I5,D:D) -> 0 | K5: =SUMIF($B:$B,$I5,E:E) -> 0 | L5: =J5-K5 -> 0
B6: =if(A6="","",TEXT(A6,"MMMM")) | F6: =if(A6="","",F5+D6-E6) | I6: May | J6: =SUMIF($B:$B,$I6,D:D) -> 0 | K6: =SUMIF($B:$B,$I6,E:E) -> 0 | L6: =J6-K6 -> 0
B7: =if(A7="","",TEXT(A7,"MMMM")) | F7: =if(A7="","",F6+D7-E7) | I7: June | J7: =SUMIF($B:$B,$I7,D:D) -> 0 | K7: =SUMIF($B:$B,$I7,E:E) -> 0 | L7: =J7-K7 -> 0
B8: =if(A8="","",TEXT(A8,"MMMM")) | F8: =if(A8="","",F7+D8-E8) | I8: July | J8: =SUMIF($B:$B,$I8,D:D) -> 0 | K8: =SUMIF($B:$B,$I8,E:E) -> 0 | L8: =J8-K8 -> 0
B9: =if(A9="","",TEXT(A9,"MMMM")) | F9: =if(A9="","",F8+D9-E9) | I9: August | J9: =SUMIF($B:$B,$I9,D:D) -> 2161750 | K9: =SUMIF($B:$B,$I9,E:E) -> 814000 | L9: =J9-K9 -> 1347750
B10: =if(A10="","",TEXT(A10,"MMMM")) | F10: =if(A10="","",F9+D10-E10) | I10: September | J10: =SUMIF($B:$B,$I10,D:D) -> 1053000 | K10: =SUMIF($B:$B,$I10,E:E) -> 1304000 | L10: =J10-K10 -> -251000
B11: =if(A11="","",TEXT(A11,"MMMM")) | F11: =if(A11="","",F10+D11-E11) | I11: October | J11: =SUMIF($B:$B,$I11,D:D) -> 0 | K11: =SUMIF($B:$B,$I11,E:E) -> 0 | L11: =J11-K11 -> 0
B12: =if(A12="","",TEXT(A12,"MMMM")) | F12: =if(A12="","",F11+D12-E12) | I12: November | J12: =SUMIF($B:$B,$I12,D:D) -> 0 | K12: =SUMIF($B:$B,$I12,E:E) -> 0 | L12: =J12-K12 -> 0
B13: =if(A13="","",TEXT(A13,"MMMM")) | F13: =if(A13="","",F12+D13-E13) | I13: December | J13: =SUMIF($B:$B,$I13,D:D) -> 0 | K13: =SUMIF($B:$B,$I13,E:E) -> 0 | L13: =J13-K13 -> 0
B14: =if(A14="","",TEXT(A14,"MMMM")) | F14: =if(A14="","",F13+D14-E14) | I14: TOTAL | J14: =SUM(J2:J13) -> 3214750 | K14: =SUM(K2:K13) -> 2118000 | L14: =SUM(L2:L13) -> 1096750
B15: =if(A15="","",TEXT(A15,"MMMM")) | F15: =if(A15="","",F14+D15-E15)
B16: =if(A16="","",TEXT(A16,"MMMM")) | F16: =if(A16="","",F15+D16-E16)
B17: =if(A17="","",TEXT(A17,"MMMM")) | F17: =if(A17="","",F16+D17-E17)
B18: =if(A18="","",TEXT(A18,"MMMM")) | F18: =if(A18="","",F17+D18-E18)
B19: =if(A19="","",TEXT(A19,"MMMM")) | F19: =if(A19="","",F18+D19-E19)
B20: =if(A20="","",TEXT(A20,"MMMM")) | F20: =if(A20="","",F19+D20-E20)
B21: =if(A21="","",TEXT(A21,"MMMM")) | F21: =if(A21="","",F20+D21-E21)
B22: =if(A22="","",TEXT(A22,"MMMM")) | F22: =if(A22="","",F21+D22-E22)
B23: =if(A23="","",TEXT(A23,"MMMM")) | F23: =if(A23="","",F22+D23-E23)
B24: =if(A24="","",TEXT(A24,"MMMM")) | F24: =if(A24="","",F23+D24-E24)
B25: =if(A25="","",TEXT(A25,"MMMM")) | F25: =if(A25="","",F24+D25-E25)
B26: =if(A26="","",TEXT(A26,"MMMM")) | F26: =if(A26="","",F25+D26-E26)
... B1000: =if(A1000="","",TEXT(A1000,"MMMM")) | F1000: =if(A1000="","",F999+D1000-E1000)

Sheet Product_cost
A1: Date | B1: Month | C1: CSR | D1: Agent | E1: Supplier | F1: Status | G1: Product | H1: Quantity | I1: Cost | J1: Waybill_Fee | N1: Month | O1: Waybilled | P1: Delivered | Q1: Balance | R1: Waybill_fee | T1: All
A2: 45901 | B2: {=IF(A2:A1000 = "", "",TEXT(A2:A1000,"mmmm"))} -> September | C2: Nuella | D2: Gologistics (Uyo) | F2: Delivered | G2: Vacuum Sealer | H2: 2 | I2: {=ifna(IF(F2="","",INDEX(UpdateSheet!W:W,MATCH(1,(UpdateSheet!U:U=MAXIFS(UpdateSheet!U:U, UpdateSheet!V:V, G2, UpdateSheet!U:U, "<=" & A2))*(UpdateSheet!V:V=G2), 0))*H2),"")} -> 19000 | N2: January | O2: =if($T$1="All",SUMIFS($I:$I,$F:$F,O$1,$B:$B,$N2),SUMIFS($I:$I,$F:$F,O$1,$B:$B,$N2,$G:$G,$T$1)) -> 0 | P2: =if($T$1="All", SUMIFS($I:$I,$F:$F,P$1,$B:$B,$N2),SUMIFS($I:$I,$F:$F,P$1,$B:$B,$N2,$G:$G,$T$1)) -> 0 | Q2: =O2-P2 -> 0 | R2: =if($T$1="All",SUMIFS($J:$J,$B:$B,$N2),SUMIFS($J:$J,$B:$B,$N2,$G:$G,$T$1)) -> 0
A3: 45901 | B3: September | C3: Nuella | D3: Gologistics (Uyo) | F3: Delivered | G3: Nylon | H3: 100 | I3: {=ifna(IF(F3="","",INDEX(UpdateSheet!W:W,MATCH(1,(UpdateSheet!U:U=MAXIFS(UpdateSheet!U:U, UpdateSheet!V:V, G3, UpdateSheet!U:U, "<=" & A3))*(UpdateSheet!V:V=G3), 0))*H3),"")} -> 15000 | N3: February | O3: =if($T$1="All",SUMIFS($I:$I,$F:$F,O$1,$B:$B,$N3),SUMIFS($I:$I,$F:$F,O$1,$B:$B,$N3,$G:$G,$T$1)) -> 0 | P3: =if($T$1="All", SUMIFS($I:$I,$F:$F,P$1,$B:$B,$N3),SUMIFS($I:$I,$F:$F,P$1,$B:$B,$N3,$G:$G,$T$1)) -> 0 | Q3: =O3-P3 -> 0 | R3: =if($T$1="All",SUMIFS($J:$J,$B:$B,$N3),SUMIFS($J:$J,$B:$B,$N3,$G:$G,$T$1)) -> 0
A4: 45902 | B4: September | C4: Nuella | D4: Eclipse Logistics | F4: Delivered | G4: Vacuum Sealer | H4: 1 | I4: {=ifna(IF(F4="","",INDEX(UpdateSheet!W:W,MATCH(1,(UpdateSheet!U:U=MAXIFS(UpdateSheet!U:U, UpdateSheet!V:V, G4, UpdateSheet!U:U, "<=" & A4))*(UpdateSheet!V:V=G4), 0))*H4),"")} -> 9500 | N4: March | O4: =if($T$1="All",SUMIFS($I:$I,$F:$F,O$1,$B:$B,$N4),SUMIFS($I:$I,$F:$F,O$1,$B:$B,$N4,$G:$G,$T$1)) -> 0 | P4: =if($T$1="All", SUMIFS($I:$I,$F:$F,P$1,$B:$B,$N4),SUMIFS($I:$I,$F:$F,P$1,$B:$B,$N4,$G:$G,$T$1)) -> 0 | Q4: =O4-P4 -> 0 | R4: =if($T$1="All",SUMIFS($J:$J,$B:$B,$N4),SUMIFS($J:$J,$B:$B,$N4,$G:$G,$T$1)) -> 0
A5: 45902 | B5: September | C5: Nuella | D5: Eclipse Logistics | F5: Delivered | G5: Nylon | H5: 50 | I5: {=ifna(IF(F5="","",INDEX(UpdateSheet!W:W,MATCH(1,(UpdateSheet!U:U=MAXIFS(UpdateSheet!U:U, UpdateSheet!V:V, G5, UpdateSheet!U:U, "<=" & A5))*(UpdateSheet!V:V=G5), 0))*H5),"")} -> 7500 | N5: April | O5: =if($T$1="All",SUMIFS($I:$I,$F:$F,O$1,$B:$B,$N5),SUMIFS($I:$I,$F:$F,O$1,$B:$B,$N5,$G:$G,$T$1)) -> 0 | P5: =if($T$1="All", SUMIFS($I:$I,$F:$F,P$1,$B:$B,$N5),SUMIFS($I:$I,$F:$F,P$1,$B:$B,$N5,$G:$G,$T$1)) -> 0 | Q5: =O5-P5 -> 0 | R5: =if($T$1="All",SUMIFS($J:$J,$B:$B,$N5),SUMIFS($J:$J,$B:$B,$N5,$G:$G,$T$1)) -> 0
A6: 45902 | B6: September | C6: Nuella | D6: Azird | F6: Delivered | G6: Vacuum Sealer | H6: 1 | I6: {=ifna(IF(F6="","",INDEX(UpdateSheet!W:W,MATCH(1,(UpdateSheet!U:U=MAXIFS(UpdateSheet!U:U, UpdateSheet!V:V, G6, UpdateSheet!U:U, "<=" & A6))*(UpdateSheet!V:V=G6), 0))*H6),"")} -> 9500 | N6: May | O6: =if($T$1="All",SUMIFS($I:$I,$F:$F,O$1,$B:$B,$N6),SUMIFS($I:$I,$F:$F,O$1,$B:$B,$N6,$G:$G,$T$1)) -> 0 | P6: =if($T$1="All", SUMIFS($I:$I,$F:$F,P$1,$B:$B,$N6),SUMIFS($I:$I,$F:$F,P$1,$B:$B,$N6,$G:$G,$T$1)) -> 0 | Q6: =O6-P6 -> 0 | R6: =if($T$1="All",SUMIFS($J:$J,$B:$B,$N6),SUMIFS($J:$J,$B:$B,$N6,$G:$G,$T$1)) -> 0
A7: 45902 | B7: September | C7: CRS1 | D7: Formax (Rivers) | F7: Delivered | G7: Smart Tablet | H7: 2 | I7: {=ifna(IF(F7="","",INDEX(UpdateSheet!W:W,MATCH(1,(UpdateSheet!U:U=MAXIFS(UpdateSheet!U:U, UpdateSheet!V:V, G7, UpdateSheet!U:U, "<=" & A7))*(UpdateSheet!V:V=G7), 0))*H7),"")} -> 24000 | N7: June | O7: =if($T$1="All",SUMIFS($I:$I,$F:$F,O$1,$B:$B,$N7),SUMIFS($I:$I,$F:$F,O$1,$B:$B,$N7,$G:$G,$T$1)) -> 0 | P7: =if($T$1="All", SUMIFS($I:$I,$F:$F,P$1,$B:$B,$N7),SUMIFS($I:$I,$F:$F,P$1,$B:$B,$N7,$G:$G,$T$1)) -> 0 | Q7: =O7-P7 -> 0 | R7: =if($T$1="All",SUMIFS($J:$J,$B:$B,$N7),SUMIFS($J:$J,$B:$B,$N7,$G:$G,$T$1)) -> 0
A8: 45903 | B8: September | C8: CRS1 | D8: Quickwaka | F8: Delivered | G8: Smart Tablet | H8: 2 | I8: {=ifna(IF(F8="","",INDEX(UpdateSheet!W:W,MATCH(1,(UpdateSheet!U:U=MAXIFS(UpdateSheet!U:U, UpdateSheet!V:V, G8, UpdateSheet!U:U, "<=" & A8))*(UpdateSheet!V:V=G8), 0))*H8),"")} -> 24000 | N8: July | O8: =if($T$1="All",SUMIFS($I:$I,$F:$F,O$1,$B:$B,$N8),SUMIFS($I:$I,$F:$F,O$1,$B:$B,$N8,$G:$G,$T$1)) -> 0 | P8: =if($T$1="All", SUMIFS($I:$I,$F:$F,P$1,$B:$B,$N8),SUMIFS($I:$I,$F:$F,P$1,$B:$B,$N8,$G:$G,$T$1)) -> 0 | Q8: =O8-P8 -> 0 | R8: =if($T$1="All",SUMIFS($J:$J,$B:$B,$N8),SUMIFS($J:$J,$B:$B,$N8,$G:$G,$T$1)) -> 0
A9: 45903 | B9: September | C9: Nuella | D9: Fomax | F9: Delivered | G9: Vacuum Sealer | H9: 1 | I9: {=ifna(IF(F9="","",INDEX(UpdateSheet!W:W,MATCH(1,(UpdateSheet!U:U=MAXIFS(UpdateSheet!U:U, UpdateSheet!V:V, G9, UpdateSheet!U:U, "<=" & A9))*(UpdateSheet!V:V=G9), 0))*H9),"")} -> 9500 | N9: August | O9: =if($T$1="All",SUMIFS($I:$I,$F:$F,O$1,$B:$B,$N9),SUMIFS($I:$I,$F:$F,O$1,$B:$B,$N9,$G:$G,$T$1)) -> 0 | P9: =if($T$1="All", SUMIFS($I:$I,$F:$F,P$1,$B:$B,$N9),SUMIFS($I:$I,$F:$F,P$1,$B:$B,$N9,$G:$G,$T$1)) -> 0 | Q9: =O9-P9 -> 0 | R9: =if($T$1="All",SUMIFS($J:$J,$B:$B,$N9),SUMIFS($J:$J,$B:$B,$N9,$G:$G,$T$1)) -> 0
A10: 45903 | B10: September | C10: Nuella | D10: Gologistics (Calabar) | F10: Delivered | G10: Vacuum Sealer | H10: 1 | I10: {=ifna(IF(F10="","",INDEX(UpdateSheet!W:W,MATCH(1,(UpdateSheet!U:U=MAXIFS(UpdateSheet!U:U, UpdateSheet!V:V, G10, UpdateSheet!U:U, "<=" & A10))*(UpdateSheet!V:V=G10), 0))*H10),"")} -> 9500 | N10: September | O10: =if($T$1="All",SUMIFS($I:$I,$F:$F,O$1,$B:$B,$N10),SUMIFS($I:$I,$F:$F,O$1,$B:$B,$N10,$G:$G,$T$1)) -> 1053000 | P10: =if($T$1="All", SUMIFS($I:$I,$F:$F,P$1,$B:$B,$N10),SUMIFS($I:$I,$F:$F,P$1,$B:$B,$N10,$G:$G,$T$1)) -> 1361500 | Q10: =O10-P10 -> -308500 | R10: =if($T$1="All",SUMIFS($J:$J,$B:$B,$N10),SUMIFS($J:$J,$B:$B,$N10,$G:$G,$T$1)) -> 51500
A11: 45903 | B11: September | C11: Nuella | D11: Gologistics (Calabar) | F11: Delivered | G11: Nylon | H11: 100 | I11: {=ifna(IF(F11="","",INDEX(UpdateSheet!W:W,MATCH(1,(UpdateSheet!U:U=MAXIFS(UpdateSheet!U:U, UpdateSheet!V:V, G11, UpdateSheet!U:U, "<=" & A11))*(UpdateSheet!V:V=G11), 0))*H11),"")} -> 15000 | N11: October | O11: =if($T$1="All",SUMIFS($I:$I,$F:$F,O$1,$B:$B,$N11),SUMIFS($I:$I,$F:$F,O$1,$B:$B,$N11,$G:$G,$T$1)) -> 1569000 | P11: =if($T$1="All", SUMIFS($I:$I,$F:$F,P$1,$B:$B,$N11),SUMIFS($I:$I,$F:$F,P$1,$B:$B,$N11,$G:$G,$T$1)) -> 940000 | Q11: =O11-P11 -> 629000 | R11: =if($T$1="All",SUMIFS($J:$J,$B:$B,$N11),SUMIFS($J:$J,$B:$B,$N11,$G:$G,$T$1)) -> 72500
A12: 45903 | B12: September | C12: Nuella | D12: Delvit (Enugu) | F12: Delivered | G12: Vacuum Sealer | H12: 1 | I12: {=ifna(IF(F12="","",INDEX(UpdateSheet!W:W,MATCH(1,(UpdateSheet!U:U=MAXIFS(UpdateSheet!U:U, UpdateSheet!V:V, G12, UpdateSheet!U:U, "<=" & A12))*(UpdateSheet!V:V=G12), 0))*H12),"")} -> 9500 | N12: November | O12: =if($T$1="All",SUMIFS($I:$I,$F:$F,O$1,$B:$B,$N12),SUMIFS($I:$I,$F:$F,O$1,$B:$B,$N12,$G:$G,$T$1)) -> 653500 | P12: =if($T$1="All", SUMIFS($I:$I,$F:$F,P$1,$B:$B,$N12),SUMIFS($I:$I,$F:$F,P$1,$B:$B,$N12,$G:$G,$T$1)) -> 874000 | Q12: =O12-P12 -> -220500 | R12: =if($T$1="All",SUMIFS($J:$J,$B:$B,$N12),SUMIFS($J:$J,$B:$B,$N12,$G:$G,$T$1)) -> 37500
A13: 45903 | B13: September | C13: Nuella | D13: HS_Logistics | F13: Delivered | G13: Vacuum Sealer | H13: 1 | I13: {=ifna(IF(F13="","",INDEX(UpdateSheet!W:W,MATCH(1,(UpdateSheet!U:U=MAXIFS(UpdateSheet!U:U, UpdateSheet!V:V, G13, UpdateSheet!U:U, "<=" & A13))*(UpdateSheet!V:V=G13), 0))*H13),"")} -> 9500 | N13: December | O13: =if($T$1="All",SUMIFS($I:$I,$F:$F,O$1,$B:$B,$N13),SUMIFS($I:$I,$F:$F,O$1,$B:$B,$N13,$G:$G,$T$1)) -> 0 | P13: =if($T$1="All", SUMIFS($I:$I,$F:$F,P$1,$B:$B,$N13),SUMIFS($I:$I,$F:$F,P$1,$B:$B,$N13,$G:$G,$T$1)) -> 0 | Q13: =O13-P13 -> 0 | R13: =if($T$1="All",SUMIFS($J:$J,$B:$B,$N13),SUMIFS($J:$J,$B:$B,$N13,$G:$G,$T$1)) -> 0
A14: 45904 | B14: September | C14: Nuella | D14: Peng_Logistics | F14: Delivered | G14: Vacuum Sealer | H14: 1 | I14: {=ifna(IF(F14="","",INDEX(UpdateSheet!W:W,MATCH(1,(UpdateSheet!U:U=MAXIFS(UpdateSheet!U:U, UpdateSheet!V:V, G14, UpdateSheet!U:U, "<=" & A14))*(UpdateSheet!V:V=G14), 0))*H14),"")} -> 9500 | N14: TOTAL | O14: =SUM(O2:O13) -> 3275500 | P14: =SUM(P2:P13) -> 3175500 | Q14: =SUM(Q2:Q13) -> 100000 | R14: =SUM(R2:R13) -> 161500
A15: 45904 | B15: September | C15: Nuella | D15: Fomax | F15: Delivered | G15: Vacuum Sealer | H15: 1 | I15: {=ifna(IF(F15="","",INDEX(UpdateSheet!W:W,MATCH(1,(UpdateSheet!U:U=MAXIFS(UpdateSheet!U:U, UpdateSheet!V:V, G15, UpdateSheet!U:U, "<=" & A15))*(UpdateSheet!V:V=G15), 0))*H15),"")} -> 9500
A16: 45904 | B16: September | C16: Nuella | D16: Gologistics (Calabar) | F16: Delivered | G16: Vacuum Sealer | H16: 1 | I16: {=ifna(IF(F16="","",INDEX(UpdateSheet!W:W,MATCH(1,(UpdateSheet!U:U=MAXIFS(UpdateSheet!U:U, UpdateSheet!V:V, G16, UpdateSheet!U:U, "<=" & A16))*(UpdateSheet!V:V=G16), 0))*H16),"")} -> 9500
A17: 45904 | B17: September | C17: CRS1 | D17: Fomax | F17: Delivered | G17: Smart Tablet | H17: 4 | I17: {=ifna(IF(F17="","",INDEX(UpdateSheet!W:W,MATCH(1,(UpdateSheet!U:U=MAXIFS(UpdateSheet!U:U, UpdateSheet!V:V, G17, UpdateSheet!U:U, "<=" & A17))*(UpdateSheet!V:V=G17), 0))*H17),"")} -> 48000
A18: 45904 | B18: September | C18: CRS1 | D18: Adebayo | F18: Delivered | G18: Smart Tablet | H18: 1 | I18: {=ifna(IF(F18="","",INDEX(UpdateSheet!W:W,MATCH(1,(UpdateSheet!U:U=MAXIFS(UpdateSheet!U:U, UpdateSheet!V:V, G18, UpdateSheet!U:U, "<=" & A18))*(UpdateSheet!V:V=G18), 0))*H18),"")} -> 12000
A19: 45905 | B19: September | C19: Nuella | D19: Samsucc Logistics | F19: Delivered | G19: Vacuum Sealer | H19: 1 | I19: {=ifna(IF(F19="","",INDEX(UpdateSheet!W:W,MATCH(1,(UpdateSheet!U:U=MAXIFS(UpdateSheet!U:U, UpdateSheet!V:V, G19, UpdateSheet!U:U, "<=" & A19))*(UpdateSheet!V:V=G19), 0))*H19),"")} -> 9500
A20: 45905 | B20: September | C20: Nuella | D20: Samsucc Logistics | F20: Delivered | G20: Nylon | H20: 50 | I20: {=ifna(IF(F20="","",INDEX(UpdateSheet!W:W,MATCH(1,(UpdateSheet!U:U=MAXIFS(UpdateSheet!U:U, UpdateSheet!V:V, G20, UpdateSheet!U:U, "<=" & A20))*(UpdateSheet!V:V=G20), 0))*H20),"")} -> 7500
A21: 45905 | B21: September | C21: Nuella | D21: Formax (Rivers) | F21: Delivered | G21: Vacuum Sealer | H21: 1 | I21: {=ifna(IF(F21="","",INDEX(UpdateSheet!W:W,MATCH(1,(UpdateSheet!U:U=MAXIFS(UpdateSheet!U:U, UpdateSheet!V:V, G21, UpdateSheet!U:U, "<=" & A21))*(UpdateSheet!V:V=G21), 0))*H21),"")} -> 9500
A22: 45905 | B22: September | C22: Nuella | D22: Aba logistics | F22: Delivered | G22: Vacuum Sealer | H22: 1 | I22: {=ifna(IF(F22="","",INDEX(UpdateSheet!W:W,MATCH(1,(UpdateSheet!U:U=MAXIFS(UpdateSheet!U:U, UpdateSheet!V:V, G22, UpdateSheet!U:U, "<=" & A22))*(UpdateSheet!V:V=G22), 0))*H22),"")} -> 9500
A23: 45905 | B23: September | C23: Nuella | D23: Aba logistics | F23: Delivered | G23: Nylon | H23: 50 | I23: {=ifna(IF(F23="","",INDEX(UpdateSheet!W:W,MATCH(1,(UpdateSheet!U:U=MAXIFS(UpdateSheet!U:U, UpdateSheet!V:V, G23, UpdateSheet!U:U, "<=" & A23))*(UpdateSheet!V:V=G23), 0))*H23),"")} -> 7500
A24: 45906 | B24: September | C24: Nuella | D24: Fomax | F24: Delivered | G24: Vacuum Sealer | H24: 1 | I24: {=ifna(IF(F24="","",INDEX(UpdateSheet!W:W,MATCH(1,(UpdateSheet!U:U=MAXIFS(UpdateSheet!U:U, UpdateSheet!V:V, G24, UpdateSheet!U:U, "<=" & A24))*(UpdateSheet!V:V=G24), 0))*H24),"")} -> 9500
A25: 45906 | B25: September | C25: Nuella | D25: Fomax | F25: Delivered | G25: Nylon | H25: 100 | I25: {=ifna(IF(F25="","",INDEX(UpdateSheet!W:W,MATCH(1,(UpdateSheet!U:U=MAXIFS(UpdateSheet!U:U, UpdateSheet!V:V, G25, UpdateSheet!U:U, "<=" & A25))*(UpdateSheet!V:V=G25), 0))*H25),"")} -> 15000
A26: 45906 | B26: September | C26: Nuella | D26: Gologistics (Calabar) | F26: Waybilled | G26: Vacuum Sealer | H26: 3 | I26: {=ifna(IF(F26="","",INDEX(UpdateSheet!W:W,MATCH(1,(UpdateSheet!U:U=MAXIFS(UpdateSheet!U:U, UpdateSheet!V:V, G26, UpdateSheet!U:U, "<=" & A26))*(UpdateSheet!V:V=G26), 0))*H26),"")} -> 28500 | J26: 5000
A27: 45906 | B27: September | C27: Nuella | D27: Gologistics (Calabar) | F27: Waybilled | G27: Nylon | H27: 100 | I27: {=ifna(IF(F27="","",INDEX(UpdateSheet!W:W,MATCH(1,(UpdateSheet!U:U=MAXIFS(UpdateSheet!U:U, UpdateSheet!V:V, G27, UpdateSheet!U:U, "<=" & A27))*(UpdateSheet!V:V=G27), 0))*H27),"")} -> 15000
A28: 45906 | B28: September | C28: Nuella | D28: Gologistics (Uyo) | F28: Waybilled | G28: Vacuum Sealer | H28: 3 | I28: {=ifna(IF(F28="","",INDEX(UpdateSheet!W:W,MATCH(1,(UpdateSheet!U:U=MAXIFS(UpdateSheet!U:U, UpdateSheet!V:V, G28, UpdateSheet!U:U, "<=" & A28))*(UpdateSheet!V:V=G28), 0))*H28),"")} -> 28500 | J28: 4000
A29: 45906 | B29: September | C29: CRS1 | D29: Samsucc Logistics | F29: Delivered | G29: Smart Tablet | H29: 1 | I29: {=ifna(IF(F29="","",INDEX(UpdateSheet!W:W,MATCH(1,(UpdateSheet!U:U=MAXIFS(UpdateSheet!U:U, UpdateSheet!V:V, G29, UpdateSheet!U:U, "<=" & A29))*(UpdateSheet!V:V=G29), 0))*H29),"")} -> 12000
A30: 45908 | B30: September | C30: Nuella | D30: Azird | F30: Delivered | G30: Vacuum Sealer | H30: 1 | I30: {=ifna(IF(F30="","",INDEX(UpdateSheet!W:W,MATCH(1,(UpdateSheet!U:U=MAXIFS(UpdateSheet!U:U, UpdateSheet!V:V, G30, UpdateSheet!U:U, "<=" & A30))*(UpdateSheet!V:V=G30), 0))*H30),"")} -> 9500
A31: 45908 | B31: September | C31: Nuella | D31: Fomax | F31: Delivered | G31: Vacuum Sealer | H31: 1 | I31: {=ifna(IF(F31="","",INDEX(UpdateSheet!W:W,MATCH(1,(UpdateSheet!U:U=MAXIFS(UpdateSheet!U:U, UpdateSheet!V:V, G31, UpdateSheet!U:U, "<=" & A31))*(UpdateSheet!V:V=G31), 0))*H31),"")} -> 9500
A32: 45908 | B32: September | C32: Nuella | D32: Fomax | F32: Delivered | G32: Nylon | H32: 50 | I32: {=ifna(IF(F32="","",INDEX(UpdateSheet!W:W,MATCH(1,(UpdateSheet!U:U=MAXIFS(UpdateSheet!U:U, UpdateSheet!V:V, G32, UpdateSheet!U:U, "<=" & A32))*(UpdateSheet!V:V=G32), 0))*H32),"")} -> 7500
A33: 45908 | B33: September | C33: Nuella | D33: Fomax | F33: Delivered | G33: Vacuum Sealer | H33: 3 | I33: {=ifna(IF(F33="","",INDEX(UpdateSheet!W:W,MATCH(1,(UpdateSheet!U:U=MAXIFS(UpdateSheet!U:U, UpdateSheet!V:V, G33, UpdateSheet!U:U, "<=" & A33))*(UpdateSheet!V:V=G33), 0))*H33),"")} -> 28500
A34: 45909 | B34: September | C34: Nuella | D34: Adebayo | F34: Waybilled | G34: Vacuum Sealer | H34: 2 | I34: {=ifna(IF(F34="","",INDEX(UpdateSheet!W:W,MATCH(1,(UpdateSheet!U:U=MAXIFS(UpdateSheet!U:U, UpdateSheet!V:V, G34, UpdateSheet!U:U, "<=" & A34))*(UpdateSheet!V:V=G34), 0))*H34),"")} -> 19000 | J34: 5000
A35: 45909 | B35: September | C35: Nuella | D35: Adebayo | F35: Waybilled | G35: Nylon | H35: 50 | I35: {=ifna(IF(F35="","",INDEX(UpdateSheet!W:W,MATCH(1,(UpdateSheet!U:U=MAXIFS(UpdateSheet!U:U, UpdateSheet!V:V, G35, UpdateSheet!U:U, "<=" & A35))*(UpdateSheet!V:V=G35), 0))*H35),"")} -> 7500
A36: 45909 | B36: September | C36: Nuella | D36: Peng_Logistics | F36: Waybilled | G36: Nylon | H36: 150 | I36: {=ifna(IF(F36="","",INDEX(UpdateSheet!W:W,MATCH(1,(UpdateSheet!U:U=MAXIFS(UpdateSheet!U:U, UpdateSheet!V:V, G36, UpdateSheet!U:U, "<=" & A36))*(UpdateSheet!V:V=G36), 0))*H36),"")} -> 22500 | J36: 4000
A37: 45909 | B37: September | C37: Nuella | D37: Azird | F37: Delivered | G37: Vacuum Sealer | H37: 1 | I37: {=ifna(IF(F37="","",INDEX(UpdateSheet!W:W,MATCH(1,(UpdateSheet!U:U=MAXIFS(UpdateSheet!U:U, UpdateSheet!V:V, G37, UpdateSheet!U:U, "<=" & A37))*(UpdateSheet!V:V=G37), 0))*H37),"")} -> 9500
A38: 45911 | B38: September | C38: Nuella | D38: Azird | F38: Delivered | G38: Vacuum Sealer | H38: 1 | I38: {=ifna(IF(F38="","",INDEX(UpdateSheet!W:W,MATCH(1,(UpdateSheet!U:U=MAXIFS(UpdateSheet!U:U, UpdateSheet!V:V, G38, UpdateSheet!U:U, "<=" & A38))*(UpdateSheet!V:V=G38), 0))*H38),"")} -> 9500
A39: 45911 | B39: September | C39: Nuella | D39: Azird | F39: Delivered | G39: Nylon | H39: 100 | I39: {=ifna(IF(F39="","",INDEX(UpdateSheet!W:W,MATCH(1,(UpdateSheet!U:U=MAXIFS(UpdateSheet!U:U, UpdateSheet!V:V, G39, UpdateSheet!U:U, "<=" & A39))*(UpdateSheet!V:V=G39), 0))*H39),"")} -> 15000
A40: 45911 | B40: September | C40: Nuella | D40: Eclipse Logistics | F40: Delivered | G40: Vacuum Sealer | H40: 2 | I40: {=ifna(IF(F40="","",INDEX(UpdateSheet!W:W,MATCH(1,(UpdateSheet!U:U=MAXIFS(UpdateSheet!U:U, UpdateSheet!V:V, G40, UpdateSheet!U:U, "<=" & A40))*(UpdateSheet!V:V=G40), 0))*H40),"")} -> 19000
...

Sheet Agent Expense
A1: Date | B1: Month | C1: Category | D1: Amount | E1: Agent | I1: Month | J1: =O1 -> All | O1: All
A2: 45934 | B2: {=IF(A2:A1000 = "", "",TEXT(A2:A1000,"mmmm"))} -> October | C2: Pickup | D2: 4500 | E2: Gologistics (Calabar) | I2: January | J2: =if($O$1="All",SUMIFS($D:$D,$B:$B,$I2),SUMIFS($D:$D,$B:$B,$I2,$C:$C,$O$1)) -> 0
A3: 45937 | B3: October | C3: Storekeeper | D3: 1000 | E3: Drop goods _Logistics | I3: February | J3: =if($O$1="All",SUMIFS($D:$D,$B:$B,$I3),SUMIFS($D:$D,$B:$B,$I3,$C:$C,$O$1)) -> 0
A4: 45947 | B4: October | C4: Pickup | D4: 1000 | E4: Adebayo | I4: March | J4: =if($O$1="All",SUMIFS($D:$D,$B:$B,$I4),SUMIFS($D:$D,$B:$B,$I4,$C:$C,$O$1)) -> 0
A5: 45948 | B5: October | C5: Failed Delivery | D5: 4000 | E5: Delvit (Enugu) | I5: April | J5: =if($O$1="All",SUMIFS($D:$D,$B:$B,$I5),SUMIFS($D:$D,$B:$B,$I5,$C:$C,$O$1)) -> 0
A6: 45951 | B6: October | C6: Pickup | D6: 2500 | E6: Delvit (Enugu) | I6: May | J6: =if($O$1="All",SUMIFS($D:$D,$B:$B,$I6),SUMIFS($D:$D,$B:$B,$I6,$C:$C,$O$1)) -> 0
A7: 45951 | B7: October | C7: Failed Delivery | D7: 3000 | E7: Kings Errand Logistics | I7: June | J7: =if($O$1="All",SUMIFS($D:$D,$B:$B,$I7),SUMIFS($D:$D,$B:$B,$I7,$C:$C,$O$1)) -> 0
A8: 45954 | B8: October | C8: Pickup | D8: 1000 | E8: Fomax | I8: July | J8: =if($O$1="All",SUMIFS($D:$D,$B:$B,$I8),SUMIFS($D:$D,$B:$B,$I8,$C:$C,$O$1)) -> 0
A9: 45958 | B9: October | C9: Pickup | D9: 2000 | E9: Eclipse Logistics | I9: August | J9: =if($O$1="All",SUMIFS($D:$D,$B:$B,$I9),SUMIFS($D:$D,$B:$B,$I9,$C:$C,$O$1)) -> 0
A10: 45960 | B10: October | C10: Failed Delivery | D10: 2000 | E10: Kings Errand Logistics | I10: September | J10: =if($O$1="All",SUMIFS($D:$D,$B:$B,$I10),SUMIFS($D:$D,$B:$B,$I10,$C:$C,$O$1)) -> 0
A11: 45961 | B11: October | C11: Pickup | D11: 500 | E11: Eclipse Logistics | I11: October | J11: =if($O$1="All",SUMIFS($D:$D,$B:$B,$I11),SUMIFS($D:$D,$B:$B,$I11,$C:$C,$O$1)) -> 21500
A12: 45962 | B12: November | C12: Pickup | D12: 1500 | E12: Formax (Rivers) | I12: November | J12: =if($O$1="All",SUMIFS($D:$D,$B:$B,$I12),SUMIFS($D:$D,$B:$B,$I12,$C:$C,$O$1)) -> 23000
A13: 45967 | B13: November | C13: Pickup | D13: 1500 | E13: Kings Errand Logistics | I13: December | J13: =if($O$1="All",SUMIFS($D:$D,$B:$B,$I13),SUMIFS($D:$D,$B:$B,$I13,$C:$C,$O$1)) -> 0
A14: 45968 | B14: November | C14: Failed Delivery | D14: 4000 | E14: Kings Errand Logistics | I14: TOTAL | J14: =SUM(J2:J13) -> 44500
A15: 45969 | B15: November | C15: Failed Delivery | D15: 2500 | E15: Samsucc Logistics
A16: 45971 | B16: November | C16: Failed Delivery | D16: 3500 | E16: Delvit (Enugu)
A17: 45974 | B17: November | C17: Pickup | D17: 2500 | E17: Eclipse Logistics
A18: 45979 | B18: November | C18: Failed Delivery | D18: 2500 | E18: Samsucc Logistics
A19: 45983 | B19: November | C19: Pickup | D19: 1500 | E19: Fomax
A20: 45983 | B20: November | C20: Pickup | D20: 1500 | E20: Formax (Rivers)
A21: 45985 | B21: November | C21: Pickup | D21: 1000 | E21: Delvit (Enugu)
A22: 45985 | B22: November | C22: Storekeeper | D22: 1000 | E22: Samsucc Logistics

Sheet Nuella
A1: Customer_Name | B1: Phone_number | C1: Location | D1: Order_Date | E1: Order_Month | F1: Order_Year | G1: Product_Name | H1: Mail_Quan | I1: Agent_Quan | J1: Quantity | K1: Product2 | L1: Mail_Quan2 | M1: Agent_Quan2 | N1: Quantity2 | O1: Cost_Price | P1: Delivery_Fee | Q1: Sales_Price | R1: Profit | S1: Order_Status | T1: Delivery_Date | U1: Delivery_Month | V1: Delivery_Year | W1: Confirmed_Delievery | X1: Agent_Name | Y1: Note | Z1: Subject
A2: Tabe Ayuk | B2: 8033332593 | C2: Abuja | D2: 45785.266 | E2: {=IF(D2:D6073 = "", "",TEXT(D2:D6073,"mmmm"))} -> May | F2: {=IF(D2:D6073 = "", "",TEXT(D2:D6073,"YYYY"))} -> 2025 | G2: Vacuum Sealer | H2: 1 | J2: {=IF(A2:A6073="","",IF(I2:I6073<>"",I2:I6073,H2:H6073))} -> 1 | N2: {=IF(A2:A6073="","",IF(M2:M6073<>"",M2:M6073,L2:L6073))} | O2: 9000 | Q2: {=ifna(IF(D2="","",INDEX(UpdateSheet!K:K,MATCH(1,(UpdateSheet!G:G=MAXIFS(UpdateSheet!G:G, UpdateSheet!H:H, G2, UpdateSheet!I:I, J2, UpdateSheet!G:G, "<=" & D2))*(UpdateSheet!H:H=G2) * (UpdateSheet!I:I=J2), 0))),"")} -> 35500 | R2: {=IF(Q2:Q6073="","",Q2:Q6073-(O2:O6073+P2:P6073))} -> 26500 | S2: Cancelled | U2: {=IF(T2:T6073 = "", "",TEXT(T2:T6073,"mmmm"))} | V2: {=IF(T2:T6073 = "", "",TEXT(T2:T6073,"yyyy"))} | W2: =if(T2<>"",TRUE,FALSE) -> FALSE | Y2: not so sure what happened but I called to confirm his order and then he said he received it but it's fake...
A3: Vivian Dennis | B3: 8163137073 | C3: Lagos | D3: 45785.447 | E3: May | F3: 2025 | G3: Vacuum Sealer | H3: 1 | J3: 1 | O3: 9000 | P3: 5000 | Q3: {=ifna(IF(D3="","",INDEX(UpdateSheet!K:K,MATCH(1,(UpdateSheet!G:G=MAXIFS(UpdateSheet!G:G, UpdateSheet!H:H, G3, UpdateSheet!I:I, J3, UpdateSheet!G:G, "<=" & D3))*(UpdateSheet!H:H=G3) * (UpdateSheet!I:I=J3), 0))),"")} -> 35500 | R3: 21500 | S3: Delivered | T3: 45785 | U3: May | V3: 2025 | W3: =if(T3<>"",TRUE,FALSE) -> TRUE | X3: Isioma Lagos agent
A4: Lady B | B4: 8030852161 | C4: Rivers | D4: 45786.942 | E4: May | F4: 2025 | G4: Vacuum Sealer | H4: 3 | J4: 3 | O4: 27000 | Q4: {=ifna(IF(D4="","",INDEX(UpdateSheet!K:K,MATCH(1,(UpdateSheet!G:G=MAXIFS(UpdateSheet!G:G, UpdateSheet!H:H, G4, UpdateSheet!I:I, J4, UpdateSheet!G:G, "<=" & D4))*(UpdateSheet!H:H=G4) * (UpdateSheet!I:I=J4), 0))),"")} -> 61500 | R4: 34500 | S4: =if(A4="","","Pending") -> Pending | W4: =if(T4<>"",TRUE,FALSE) -> FALSE | Y4: Not responding to both chat and call.
A5: Anna Wilson | B5: 951577367 | C5: Kano | D5: 45787.037 | E5: May | F5: 2025 | G5: Vacuum Sealer | H5: 4 | J5: 4 | O5: 36000 | Q5: {=ifna(IF(D5="","",INDEX(UpdateSheet!K:K,MATCH(1,(UpdateSheet!G:G=MAXIFS(UpdateSheet!G:G, UpdateSheet!H:H, G5, UpdateSheet!I:I, J5, UpdateSheet!G:G, "<=" & D5))*(UpdateSheet!H:H=G5) * (UpdateSheet!I:I=J5), 0))),"")} | S5: Cancelled | W5: =if(T5<>"",TRUE,FALSE) -> FALSE | Y5: invalid phone and Whatsapp number.
A6: kennethOnyemachi Onyemachi | B6: 8135660709 | C6: Rivers | D6: 45787.556 | E6: May | F6: 2025 | G6: Vacuum Sealer | H6: 1 | J6: 1 | O6: 9000 | P6: 8000 | Q6: {=ifna(IF(D6="","",INDEX(UpdateSheet!K:K,MATCH(1,(UpdateSheet!G:G=MAXIFS(UpdateSheet!G:G, UpdateSheet!H:H, G6, UpdateSheet!I:I, J6, UpdateSheet!G:G, "<=" & D6))*(UpdateSheet!H:H=G6) * (UpdateSheet!I:I=J6), 0))),"")} -> 35500 | R6: 18500 | S6: Delivered | T6: 45793 | U6: May | V6: 2025 | W6: =if(T6<>"",TRUE,FALSE) -> TRUE | X6: Sagok Logistics
A7: Comfort Chukwuka | B7: 8037267331 | C7: Lagos | D7: 45787.616 | E7: May | F7: 2025 | G7: Vacuum Sealer | H7: 1 | J7: 1 | O7: 9000 | Q7: {=ifna(IF(D7="","",INDEX(UpdateSheet!K:K,MATCH(1,(UpdateSheet!G:G=MAXIFS(UpdateSheet!G:G, UpdateSheet!H:H, G7, UpdateSheet!I:I, J7, UpdateSheet!G:G, "<=" & D7))*(UpdateSheet!H:H=G7) * (UpdateSheet!I:I=J7), 0))),"")} -> 35500 | R7: 26500 | S7: =if(A7="","","Pending") -> Pending | W7: =if(T7<>"",TRUE,FALSE) -> FALSE | Y7: Still on her case, persuading her she says it's too expensive
A8: DESOLA Daniel | B8: 8088558559 | C8: Abuja | D8: 45788.407 | E8: May | F8: 2025 | G8: Vacuum Sealer | H8: 1 | J8: 1 | O8: 9000 | P8: 5000 | Q8: {=ifna(IF(D8="","",INDEX(UpdateSheet!K:K,MATCH(1,(UpdateSheet!G:G=MAXIFS(UpdateSheet!G:G, UpdateSheet!H:H, G8, UpdateSheet!I:I, J8, UpdateSheet!G:G, "<=" & D8))*(UpdateSheet!H:H=G8) * (UpdateSheet!I:I=J8), 0))),"")} -> 35500 | R8: 21500 | S8: Delivered | T8: 45793 | U8: May | V8: 2025 | W8: =if(T8<>"",TRUE,FALSE) -> TRUE | X8: Fomax
A9: Joy Joy | B9: 8138930504 | C9: Abuja | D9: 45789.365 | E9: May | F9: 2025 | G9: Vacuum Sealer | H9: 1 | J9: 1 | O9: 9000 | P9: 5000 | Q9: {=ifna(IF(D9="","",INDEX(UpdateSheet!K:K,MATCH(1,(UpdateSheet!G:G=MAXIFS(UpdateSheet!G:G, UpdateSheet!H:H, G9, UpdateSheet!I:I, J9, UpdateSheet!G:G, "<=" & D9))*(UpdateSheet!H:H=G9) * (UpdateSheet!I:I=J9), 0))),"")} -> 35500 | R9: 21500 | S9: Delivered | T9: 45793 | U9: May | V9: 2025 | W9: =if(T9<>"",TRUE,FALSE) -> TRUE | X9: Fomax | Z9: =sumif(S:S,"Delivered",J:J) -> 599
A10: Madu simeon simeon | B10: 7036133915 | C10: Kano | D10: 45790.437 | E10: May | F10: 2025 | G10: Vacuum Sealer | H10: 2 | J10: 2 | O10: 18000 | P10: 6500 | Q10: {=ifna(IF(D10="","",INDEX(UpdateSheet!K:K,MATCH(1,(UpdateSheet!G:G=MAXIFS(UpdateSheet!G:G, UpdateSheet!H:H, G10, UpdateSheet!I:I, J10, UpdateSheet!G:G, "<=" & D10))*(UpdateSheet!H:H=G10) * (UpdateSheet!I:I=J10), 0))),"")} -> 49500 | R10: 25000 | S10: Delivered | T10: 45799 | U10: May | V10: 2025 | W10: =if(T10<>"",TRUE,FALSE) -> TRUE | X10: Vikaad (Kano)
A11: Ogonna Ifebi | B11: 8038850444 | C11: Anambra | D11: 45790.48 | E11: May | F11: 2025 | G11: Vacuum Sealer | H11: 1 | J11: 1 | O11: 9000 | P11: 7500 | Q11: {=ifna(IF(D11="","",INDEX(UpdateSheet!K:K,MATCH(1,(UpdateSheet!G:G=MAXIFS(UpdateSheet!G:G, UpdateSheet!H:H, G11, UpdateSheet!I:I, J11, UpdateSheet!G:G, "<=" & D11))*(UpdateSheet!H:H=G11) * (UpdateSheet!I:I=J11), 0))),"")} -> 35500 | R11: 19000 | S11: Delivered | T11: 45794 | U11: May | V11: 2025 | W11: =if(T11<>"",TRUE,FALSE) -> TRUE | X11: HS_Logistics
A12: John Awe | B12: 8055882226 | C12: Delta | D12: 45790.862 | E12: May | F12: 2025 | G12: Vacuum Sealer | H12: 1 | J12: 1 | O12: 9000 | P12: 5500 | Q12: {=ifna(IF(D12="","",INDEX(UpdateSheet!K:K,MATCH(1,(UpdateSheet!G:G=MAXIFS(UpdateSheet!G:G, UpdateSheet!H:H, G12, UpdateSheet!I:I, J12, UpdateSheet!G:G, "<=" & D12))*(UpdateSheet!H:H=G12) * (UpdateSheet!I:I=J12), 0))),"")} -> 35500 | R12: 21000 | S12: Delivered | T12: 45794 | U12: May | V12: 2025 | W12: =if(T12<>"",TRUE,FALSE) -> TRUE | X12: Kings_Store
A13: Hamza Malami | B13: 8038069680 | C13: Zamfara | D13: 45791.913 | E13: May | F13: 2025 | G13: Vacuum Sealer | H13: 1 | J13: 1 | O13: 9000 | P13: 5000 | Q13: {=ifna(IF(D13="","",INDEX(UpdateSheet!K:K,MATCH(1,(UpdateSheet!G:G=MAXIFS(UpdateSheet!G:G, UpdateSheet!H:H, G13, UpdateSheet!I:I, J13, UpdateSheet!G:G, "<=" & D13))*(UpdateSheet!H:H=G13) * (UpdateSheet!I:I=J13), 0))),"")} -> 35500 | R13: 21500 | S13: Delivered | T13: 45798 | U13: May | V13: 2025 | W13: =if(T13<>"",TRUE,FALSE) -> TRUE | X13: Vikaad (Kano)
A14: John Ih | B14: 9169850690 | C14: Rivers | D14: 45791.93 | E14: May | F14: 2025 | G14: Vacuum Sealer | H14: 2 | J14: 2 | O14: 18000 | P14: 9000 | Q14: {=ifna(IF(D14="","",INDEX(UpdateSheet!K:K,MATCH(1,(UpdateSheet!G:G=MAXIFS(UpdateSheet!G:G, UpdateSheet!H:H, G14, UpdateSheet!I:I, J14, UpdateSheet!G:G, "<=" & D14))*(UpdateSheet!H:H=G14) * (UpdateSheet!I:I=J14), 0))),"")} -> 49500 | R14: 22500 | S14: Delivered | T14: 45799 | U14: May | V14: 2025 | W14: =if(T14<>"",TRUE,FALSE) -> TRUE | X14: Sagok Logistics
A15: Angela Olaleye | B15: 8141813399 | C15: Lagos | D15: 45792.04 | E15: May | F15: 2025 | G15: Vacuum Sealer | H15: 1 | J15: 1 | O15: 9000 | P15: 7000 | Q15: {=ifna(IF(D15="","",INDEX(UpdateSheet!K:K,MATCH(1,(UpdateSheet!G:G=MAXIFS(UpdateSheet!G:G, UpdateSheet!H:H, G15, UpdateSheet!I:I, J15, UpdateSheet!G:G, "<=" & D15))*(UpdateSheet!H:H=G15) * (UpdateSheet!I:I=J15), 0))),"")} -> 35500 | R15: 19500 | S15: Delivered | T15: 45792 | U15: May | V15: 2025 | W15: =if(T15<>"",TRUE,FALSE) -> TRUE | X15: Isioma Lagos agent
A16: UKPABI MICHAEL | B16: 8062592518 | C16: Cross River | D16: 45792.096 | E16: May | F16: 2025 | G16: Vacuum Sealer | H16: 1 | J16: 1 | O16: 9000 | Q16: {=ifna(IF(D16="","",INDEX(UpdateSheet!K:K,MATCH(1,(UpdateSheet!G:G=MAXIFS(UpdateSheet!G:G, UpdateSheet!H:H, G16, UpdateSheet!I:I, J16, UpdateSheet!G:G, "<=" & D16))*(UpdateSheet!H:H=G16) * (UpdateSheet!I:I=J16), 0))),"")} -> 35500 | R16: 26500 | S16: =if(A16="","","Pending") -> Pending | W16: =if(T16<>"",TRUE,FALSE) -> FALSE | Y16: not responding to calls or chat
A17: Lucky E | B17: 8052113524 | C17: Delta | D17: 45792.207 | E17: May | F17: 2025 | G17: Vacuum Sealer | H17: 2 | J17: 2 | O17: 18000 | P17: 6000 | Q17: {=ifna(IF(D17="","",INDEX(UpdateSheet!K:K,MATCH(1,(UpdateSheet!G:G=MAXIFS(UpdateSheet!G:G, UpdateSheet!H:H, G17, UpdateSheet!I:I, J17, UpdateSheet!G:G, "<=" & D17))*(UpdateSheet!H:H=G17) * (UpdateSheet!I:I=J17), 0))),"")} -> 49500 | R17: 25500 | S17: Delivered | T17: 45796 | U17: May | V17: 2025 | W17: =if(T17<>"",TRUE,FALSE) -> TRUE | X17: Kings_Store
A18: Akindele | B18: 8066144162 | C18: Ogun | D18: 45792.534 | E18: May | F18: 2025 | G18: Vacuum Sealer | H18: 1 | J18: 1 | O18: 9000 | P18: 5000 | Q18: {=ifna(IF(D18="","",INDEX(UpdateSheet!K:K,MATCH(1,(UpdateSheet!G:G=MAXIFS(UpdateSheet!G:G, UpdateSheet!H:H, G18, UpdateSheet!I:I, J18, UpdateSheet!G:G, "<=" & D18))*(UpdateSheet!H:H=G18) * (UpdateSheet!I:I=J18), 0))),"")} -> 35500 | R18: 21500 | S18: Delivered | T18: 45796 | U18: May | V18: 2025 | W18: =if(T18<>"",TRUE,FALSE) -> TRUE | X18: Soshine
A19: EJIRE SAMUEL MBELE | B19: 8037057416 | C19: Rivers | D19: 45792.702 | E19: May | F19: 2025 | G19: Vacuum Sealer | H19: 1 | J19: 1 | O19: 9000 | P19: 5000 | Q19: {=ifna(IF(D19="","",INDEX(UpdateSheet!K:K,MATCH(1,(UpdateSheet!G:G=MAXIFS(UpdateSheet!G:G, UpdateSheet!H:H, G19, UpdateSheet!I:I, J19, UpdateSheet!G:G, "<=" & D19))*(UpdateSheet!H:H=G19) * (UpdateSheet!I:I=J19), 0))),"")} -> 35500 | R19: 21500 | S19: Delivered | T19: 45798 | U19: May | V19: 2025 | W19: =if(T19<>"",TRUE,FALSE) -> TRUE | X19: Sagok Logistics
A20: Akomolafe Gideon | B20: 7035545517 | C20: Osun | D20: 45792.726 | E20: May | F20: 2025 | G20: Vacuum Sealer | H20: 1 | J20: 1 | O20: 9000 | Q20: {=ifna(IF(D20="","",INDEX(UpdateSheet!K:K,MATCH(1,(UpdateSheet!G:G=MAXIFS(UpdateSheet!G:G, UpdateSheet!H:H, G20, UpdateSheet!I:I, J20, UpdateSheet!G:G, "<=" & D20))*(UpdateSheet!H:H=G20) * (UpdateSheet!I:I=J20), 0))),"")} -> 35500 | R20: 26500 | S20: Delivered | T20: 45819 | U20: June | V20: 2025 | W20: =if(T20<>"",TRUE,FALSE) -> TRUE | X20: Eclipse Logistics
A21: Amuwa Josephine | B21: 8035897470 | C21: Abuja | D21: 45792.734 | E21: May | F21: 2025 | G21: Vacuum Sealer | H21: 1 | J21: 1 | O21: 9000 | Q21: {=ifna(IF(D21="","",INDEX(UpdateSheet!K:K,MATCH(1,(UpdateSheet!G:G=MAXIFS(UpdateSheet!G:G, UpdateSheet!H:H, G21, UpdateSheet!I:I, J21, UpdateSheet!G:G, "<=" & D21))*(UpdateSheet!H:H=G21) * (UpdateSheet!I:I=J21), 0))),"")} -> 35500 | R21: 26500 | S21: Cancelled | W21: =if(T21<>"",TRUE,FALSE) -> FALSE | Y21: Product took too long to get to her and she couldn't wait.
A22: Mr eze eze | B22: 8118367267 | C22: Anambra | D22: 45792.809 | E22: May | F22: 2025 | G22: Vacuum Sealer | H22: 3 | J22: 3 | O22: 27000 | Q22: {=ifna(IF(D22="","",INDEX(UpdateSheet!K:K,MATCH(1,(UpdateSheet!G:G=MAXIFS(UpdateSheet!G:G, UpdateSheet!H:H, G22, UpdateSheet!I:I, J22, UpdateSheet!G:G, "<=" & D22))*(UpdateSheet!H:H=G22) * (UpdateSheet!I:I=J22), 0))),"")} -> 61500 | R22: 34500 | S22: =if(A22="","","Pending") -> Pending | W22: =if(T22<>"",TRUE,FALSE) -> FALSE | Y22: No full address and I've reached out to him no response to it.
A23: EDIDIONG ETIM | B23: 8034127171 | C23: Imo | D23: 45793.359 | E23: May | F23: 2025 | G23: Vacuum Sealer | H23: 2 | J23: 2 | O23: 18000 | Q23: {=ifna(IF(D23="","",INDEX(UpdateSheet!K:K,MATCH(1,(UpdateSheet!G:G=MAXIFS(UpdateSheet!G:G, UpdateSheet!H:H, G23, UpdateSheet!I:I, J23, UpdateSheet!G:G, "<=" & D23))*(UpdateSheet!H:H=G23) * (UpdateSheet!I:I=J23), 0))),"")} -> 49500 | R23: 31500 | S23: Cancelled | W23: =if(T23<>"",TRUE,FALSE) -> FALSE | Y23: couldn't wait and didn't tell me she will get from another company.
A24: Anita Oke | B24: 8077767250 | C24: Lagos | D24: 45793.37 | E24: May | F24: 2025 | G24: Vacuum Sealer | H24: 1 | J24: 1 | O24: 9000 | P24: 7000 | Q24: {=ifna(IF(D24="","",INDEX(UpdateSheet!K:K,MATCH(1,(UpdateSheet!G:G=MAXIFS(UpdateSheet!G:G, UpdateSheet!H:H, G24, UpdateSheet!I:I, J24, UpdateSheet!G:G, "<=" & D24))*(UpdateSheet!H:H=G24) * (UpdateSheet!I:I=J24), 0))),"")} -> 35500 | R24: 19500 | S24: Delivered | T24: 45798 | U24: May | V24: 2025 | W24: =if(T24<>"",TRUE,FALSE) -> TRUE | X24: Isioma Lagos agent
A25: Diai stella | B25: 8037256413 | C25: Delta | D25: 45796.12 | E25: May | F25: 2025 | G25: Vacuum Sealer | H25: 1 | J25: 1 | O25: 9000 | P25: 8000 | Q25: {=ifna(IF(D25="","",INDEX(UpdateSheet!K:K,MATCH(1,(UpdateSheet!G:G=MAXIFS(UpdateSheet!G:G, UpdateSheet!H:H, G25, UpdateSheet!I:I, J25, UpdateSheet!G:G, "<=" & D25))*(UpdateSheet!H:H=G25) * (UpdateSheet!I:I=J25), 0))),"")} -> 35500 | R25: 18500 | S25: Delivered | T25: 45799 | U25: May | V25: 2025 | W25: =if(T25<>"",TRUE,FALSE) -> TRUE | X25: Kings_Store
A26: Olatunji Bola | B26: 8033131626 | C26: Nasarawa | D26: 45796.533 | E26: May | F26: 2025 | G26: Vacuum Sealer | H26: 1 | J26: 1 | O26: 9000 | P26: 6000 | Q26: {=ifna(IF(D26="","",INDEX(UpdateSheet!K:K,MATCH(1,(UpdateSheet!G:G=MAXIFS(UpdateSheet!G:G, UpdateSheet!H:H, G26, UpdateSheet!I:I, J26, UpdateSheet!G:G, "<=" & D26))*(UpdateSheet!H:H=G26) * (UpdateSheet!I:I=J26), 0))),"")} -> 35500 | R26: 20500 | S26: Delivered | T26: 45801 | U26: May | V26: 2025 | W26: =if(T26<>"",TRUE,FALSE) -> TRUE | X26: Vikaad (Nasarawa)
A27: Dorcas Amos | B27: 9048420297 | C27: Nasarawa | D27: 45796.541 | E27: May | F27: 2025 | G27: Vacuum Sealer | H27: 1 | J27: 1 | O27: 9000 | P27: 6000 | Q27: {=ifna(IF(D27="","",INDEX(UpdateSheet!K:K,MATCH(1,(UpdateSheet!G:G=MAXIFS(UpdateSheet!G:G, UpdateSheet!H:H, G27, UpdateSheet!I:I, J27, UpdateSheet!G:G, "<=" & D27))*(UpdateSheet!H:H=G27) * (UpdateSheet!I:I=J27), 0))),"")} -> 35500 | R27: 20500 | S27: Delivered | T27: 45803 | U27: May | V27: 2025 | W27: =if(T27<>"",TRUE,FALSE) -> TRUE | X27: Vikaad (Nasarawa)
A28: Chinyere Kings-Agbasiere | B28: 8038052232 | C28: Anambra | D28: 45796.648 | E28: May | F28: 2025 | G28: Vacuum Sealer | H28: 1 | J28: 1 | O28: 9000 | P28: 5000 | Q28: {=ifna(IF(D28="","",INDEX(UpdateSheet!K:K,MATCH(1,(UpdateSheet!G:G=MAXIFS(UpdateSheet!G:G, UpdateSheet!H:H, G28, UpdateSheet!I:I, J28, UpdateSheet!G:G, "<=" & D28))*(UpdateSheet!H:H=G28) * (UpdateSheet!I:I=J28), 0))),"")} -> 35500 | R28: 21500 | S28: Delivered | T28: 45804 | U28: May | V28: 2025 | W28: =if(T28<>"",TRUE,FALSE) -> TRUE | X28: HS_Logistics
A29: Jacinta Ekaji | B29: 7062116311 | C29: Abuja | D29: 45796.723 | E29: May | F29: 2025 | G29: Vacuum Sealer | H29: 1 | J29: 1 | O29: 9000 | Q29: {=ifna(IF(D29="","",INDEX(UpdateSheet!K:K,MATCH(1,(UpdateSheet!G:G=MAXIFS(UpdateSheet!G:G, UpdateSheet!H:H, G29, UpdateSheet!I:I, J29, UpdateSheet!G:G, "<=" & D29))*(UpdateSheet!H:H=G29) * (UpdateSheet!I:I=J29), 0))),"")} -> 35500 | R29: 26500 | S29: =if(A29="","","Pending") -> Pending | W29: =if(T29<>"",TRUE,FALSE) -> FALSE
A30: Helen Adetowubo | B30: 8035811342 | C30: ondo | D30: 45796.925 | E30: May | F30: 2025 | G30: Vacuum Sealer | H30: 1 | J30: 1 | O30: 9000 | P30: 5500 | Q30: {=ifna(IF(D30="","",INDEX(UpdateSheet!K:K,MATCH(1,(UpdateSheet!G:G=MAXIFS(UpdateSheet!G:G, UpdateSheet!H:H, G30, UpdateSheet!I:I, J30, UpdateSheet!G:G, "<=" & D30))*(UpdateSheet!H:H=G30) * (UpdateSheet!I:I=J30), 0))),"")} -> 35500 | R30: 21000 | S30: Delivered | T30: 45798 | U30: May | V30: 2025 | W30: =if(T30<>"",TRUE,FALSE) -> TRUE | X30: Adebayo
A31: Caroline Odu | B31: 8033082370 | C31: Lagos | D31: 45796.966 | E31: May | F31: 2025 | G31: Vacuum Sealer | H31: 1 | J31: 1 | O31: 9000 | P31: 5000 | Q31: {=ifna(IF(D31="","",INDEX(UpdateSheet!K:K,MATCH(1,(UpdateSheet!G:G=MAXIFS(UpdateSheet!G:G, UpdateSheet!H:H, G31, UpdateSheet!I:I, J31, UpdateSheet!G:G, "<=" & D31))*(UpdateSheet!H:H=G31) * (UpdateSheet!I:I=J31), 0))),"")} -> 35500 | R31: 21500 | S31: Delivered | T31: 45797 | U31: May | V31: 2025 | W31: =if(T31<>"",TRUE,FALSE) -> TRUE | X31: Isioma Lagos agent
A32: Kowe Oyetunde | B32: 7032657362 | C32: Ekiti | D32: 45798.281 | E32: May | F32: 2025 | G32: Vacuum Sealer | H32: 1 | J32: 1 | O32: 9000 | Q32: {=ifna(IF(D32="","",INDEX(UpdateSheet!K:K,MATCH(1,(UpdateSheet!G:G=MAXIFS(UpdateSheet!G:G, UpdateSheet!H:H, G32, UpdateSheet!I:I, J32, UpdateSheet!G:G, "<=" & D32))*(UpdateSheet!H:H=G32) * (UpdateSheet!I:I=J32), 0))),"")} -> 35500 | R32: 26500 | S32: =if(A32="","","Pending") -> Pending | W32: =if(T32<>"",TRUE,FALSE) -> FALSE | Y32: Product is in Ado Ekiti but customer says she'll get back to me when she gets money from her husband.
A33: Clement Otache | B33: 8066612108 | C33: Rivers | D33: 45798.332 | E33: May | F33: 2025 | G33: Vacuum Sealer | H33: 1 | J33: 1 | O33: 9000 | Q33: {=ifna(IF(D33="","",INDEX(UpdateSheet!K:K,MATCH(1,(UpdateSheet!G:G=MAXIFS(UpdateSheet!G:G, UpdateSheet!H:H, G33, UpdateSheet!I:I, J33, UpdateSheet!G:G, "<=" & D33))*(UpdateSheet!H:H=G33) * (UpdateSheet!I:I=J33), 0))),"")} -> 35500 | R33: 26500 | S33: Cancelled | W33: =if(T33<>"",TRUE,FALSE) -> FALSE | Y33: called him some minute after the order and said he has been looking for a way to cancel the order cause the wife says it's not this type she wants.
A34: Victoria pam | B34: 9017255343 | C34: Abuja | D34: 45798.346 | E34: May | F34: 2025 | G34: Vacuum Sealer | H34: 1 | J34: 1 | O34: 9000 | Q34: {=ifna(IF(D34="","",INDEX(UpdateSheet!K:K,MATCH(1,(UpdateSheet!G:G=MAXIFS(UpdateSheet!G:G, UpdateSheet!H:H, G34, UpdateSheet!I:I, J34, UpdateSheet!G:G, "<=" & D34))*(UpdateSheet!H:H=G34) * (UpdateSheet!I:I=J34), 0))),"")} -> 35500 | R34: 26500 | S34: =if(A34="","","Pending") -> Pending | W34: =if(T34<>"",TRUE,FALSE) -> FALSE | Y34: Not picking calls and replying chat and product is at Abuja
A35: Oluwatosin James | B35: 348033137236 | C35: Lagos | D35: 45798.452 | E35: May | F35: 2025 | G35: Vacuum Sealer | H35: 1 | J35: 1 | O35: 9000 | Q35: {=ifna(IF(D35="","",INDEX(UpdateSheet!K:K,MATCH(1,(UpdateSheet!G:G=MAXIFS(UpdateSheet!G:G, UpdateSheet!H:H, G35, UpdateSheet!I:I, J35, UpdateSheet!G:G, "<=" & D35))*(UpdateSheet!H:H=G35) * (UpdateSheet!I:I=J35), 0))),"")} -> 35500 | R35: 26500 | S35: Delivered | T35: 45799 | U35: May | V35: 2025 | W35: =if(T35<>"",TRUE,FALSE) -> TRUE | Y35: Isioma Lagos agent
A36: Bagi | B36: 8055178232 | C36: Abuja | D36: 45798.839 | E36: May | F36: 2025 | G36: Vacuum Sealer | H36: 1 | J36: 1 | O36: 9000 | P36: 5000 | Q36: {=ifna(IF(D36="","",INDEX(UpdateSheet!K:K,MATCH(1,(UpdateSheet!G:G=MAXIFS(UpdateSheet!G:G, UpdateSheet!H:H, G36, UpdateSheet!I:I, J36, UpdateSheet!G:G, "<=" & D36))*(UpdateSheet!H:H=G36) * (UpdateSheet!I:I=J36), 0))),"")} -> 35500 | R36: 21500 | S36: Delivered | T36: 45806 | U36: May | V36: 2025 | W36: =if(T36<>"",TRUE,FALSE) -> TRUE | X36: Fomax
A37: Benneth UMEH | B37: 7036982105 | C37: Abuja | D37: 45799.293 | E37: May | F37: 2025 | G37: Vacuum Sealer | H37: 2 | J37: 2 | O37: 18000 | Q37: {=ifna(IF(D37="","",INDEX(UpdateSheet!K:K,MATCH(1,(UpdateSheet!G:G=MAXIFS(UpdateSheet!G:G, UpdateSheet!H:H, G37, UpdateSheet!I:I, J37, UpdateSheet!G:G, "<=" & D37))*(UpdateSheet!H:H=G37) * (UpdateSheet!I:I=J37), 0))),"")} -> 49500 | R37: 31500 | S37: =if(A37="","","Pending") -> Pending | W37: =if(T37<>"",TRUE,FALSE) -> FALSE | Y37: Not responding to calls and chat
A38: Asuzu | B38: 8039621029 | C38: Abuja | D38: 45799.442 | E38: May | F38: 2025 | G38: Vacuum Sealer | H38: 1 | J38: 1 | O38: 9000 | Q38: {=ifna(IF(D38="","",INDEX(UpdateSheet!K:K,MATCH(1,(UpdateSheet!G:G=MAXIFS(UpdateSheet!G:G, UpdateSheet!H:H, G38, UpdateSheet!I:I, J38, UpdateSheet!G:G, "<=" & D38))*(UpdateSheet!H:H=G38) * (UpdateSheet!I:I=J38), 0))),"")} -> 35500 | R38: 26500 | S38: Delivered | W38: =if(T38<>"",TRUE,FALSE) -> FALSE | Y38: She cancelled, said she doesn't have money.
A39: Utoro Glory | B39: 8084469741 | C39: Rivers | D39: 45800.896 | E39: May | F39: 2025 | G39: Vacuum Sealer | H39: 2 | J39: 2 | O39: 18000 | Q39: {=ifna(IF(D39="","",INDEX(UpdateSheet!K:K,MATCH(1,(UpdateSheet!G:G=MAXIFS(UpdateSheet!G:G, UpdateSheet!H:H, G39, UpdateSheet!I:I, J39, UpdateSheet!G:G, "<=" & D39))*(UpdateSheet!H:H=G39) * (UpdateSheet!I:I=J39), 0))),"")} -> 49500 | R39: 31500 | S39: =if(A39="","","Pending") -> Pending | W39: =if(T39<>"",TRUE,FALSE) -> FALSE
A40: darling ugochi | B40: 7030308137 | C40: Imo | D40: 45801.329 | E40: May | F40: 2025 | G40: Vacuum Sealer | H40: 1 | J40: 1 | O40: 9000 | Q40: {=ifna(IF(D40="","",INDEX(UpdateSheet!K:K,MATCH(1,(UpdateSheet!G:G=MAXIFS(UpdateSheet!G:G, UpdateSheet!H:H, G40, UpdateSheet!I:I, J40, UpdateSheet!G:G, "<=" & D40))*(UpdateSheet!H:H=G40) * (UpdateSheet!I:I=J40), 0))),"")} -> 35500 | R40: 26500 | S40: Cancelled | W40: =if(T40<>"",TRUE,FALSE) -> FALSE | Y40: She said she had bought the machine before from us but made the order so she can confirm if we supply extra nylon, and we don't.
...

Sheet CRS1
A1: Customer_Name | B1: Phone_number | C1: Location | D1: Order_Date | E1: Order_Month | F1: Order_Year | G1: Product_Name | H1: Mail_Quan | I1: Agent_Quan | J1: Quantity | K1: Product2 | L1: Mail_Quan2 | M1: Agent_Quan2 | N1: Quantity2 | O1: Cost_Price | P1: Delivery_Fee | Q1: Sales_Price | R1: Profit | S1: Order_Status | T1: Delivery_Date | U1: Delivery_Month | V1: Delivery_Year | W1: Confirmed_Delievery | X1: Agent_Name | Y1: Note
A2: Innocent Amodu | B2: 8065645338 | C2: Kano | D2: 45880.379 | E2: August | F2: 2025 | G2: Smart Tablet | H2: 2 | J2: 2 | O2: 24000 | Q2: 65500 | R2: 41500 | S2: Cancelled | W2: FALSE | Y2: he thought it was 35,000 so he won't buy again
A3: Abdullahi Aliyu | B3: 9029524776 | C3: Abuja | D3: 45877.486 | E3: August | F3: 2025 | G3: Smart Tablet | H3: 1 | J3: 1 | O3: {=IF(A3="", "", (IFNA(IF(A3="", "", INDEX(UpdateSheet!$L:$L, MATCH(1, (UpdateSheet!$G:$G=MAXIFS(UpdateSheet!$G:$G, UpdateSheet!$H:$H, G3, UpdateSheet!$G:$G, "<=" & D3)) * (UpdateSheet!$H:$H=G3), 0))), "") * J3) + (IFNA(IF(A3="", "", INDEX(UpdateSheet!$P:$P, MATCH(1, (UpdateSheet!$G:$G=MAXIFS(UpdateSheet!$G:$G, UpdateSheet!$M:$M, K3, UpdateSheet!$G:$G, "<=" & D3)) * (UpdateSheet!$M:$M=K3), 0))), "") * N3) )} -> 12000 | Q3: {=IF(A3="", "", (IFNA(IF(A3="", "", INDEX(UpdateSheet!$K:$K, MATCH(1, (UpdateSheet!$G:$G=MAXIFS(UpdateSheet!$G:$G, UpdateSheet!$H:$H, G3, UpdateSheet!$I:$I, J3, UpdateSheet!$G:$G, "<=" & D3)) * (UpdateSheet!$H:$H=G3) *(UpdateSheet!$I:$I=J3), 0))), "")) + (IFNA(IF(A3="", "", INDEX(UpdateSheet!$O:$O, MATCH(1, (UpdateSheet!$G:$G=MAXIFS(UpdateSheet!$G:$G, UpdateSheet!$M:$M, K3,UpdateSheet!$N:$N, N3, UpdateSheet!$G:$G, "<=" & D3)) * (UpdateSheet!$M:$M=K3) *(UpdateSheet!$N:$N=N3), 0))), "")) )} -> 41500 | R3: 29500 | S3: Cancelled | W3: =if(T3<>"",TRUE,FALSE) -> FALSE | Y3: Already gotten somewhere else
A4: Akoji Amodu | B4: 8066122356 | C4: Bayelsa | D4: 45880.684 | E4: {=IF(D4:D1891 = "", "",TEXT(D4:D1891,"mmmm"))} -> August | F4: {=IF(D4:D1891 = "", "",TEXT(D4:D1891,"YYYY"))} -> 2025 | G4: Smart Tablet | H4: 1 | J4: {=IF(A4:A1891="","",IF(I4:I1891<>"",I4:I1891,H4:H1891))} -> 1 | K4: {=IF(A4:A1891="","",IF((L4:L1891<>"")+(M4:M1891<>""),"Nylon",""))} | N4: {=IF(A4:A1891="","",IF(M4:M1891<>"",M4:M1891,L4:L1891))} | O4: {=IF(A4="", "", (IFNA(IF(A4="", "", INDEX(UpdateSheet!$L:$L, MATCH(1, (UpdateSheet!$G:$G=MAXIFS(UpdateSheet!$G:$G, UpdateSheet!$H:$H, G4, UpdateSheet!$G:$G, "<=" & D4)) * (UpdateSheet!$H:$H=G4), 0))), "") * J4) + (IFNA(IF(A4="", "", INDEX(UpdateSheet!$P:$P, MATCH(1, (UpdateSheet!$G:$G=MAXIFS(UpdateSheet!$G:$G, UpdateSheet!$M:$M, K4, UpdateSheet!$G:$G, "<=" & D4)) * (UpdateSheet!$M:$M=K4), 0))), "") * N4) )} -> 12000 | Q4: {=IF(A4="", "", (IFNA(IF(A4="", "", INDEX(UpdateSheet!$K:$K, MATCH(1, (UpdateSheet!$G:$G=MAXIFS(UpdateSheet!$G:$G, UpdateSheet!$H:$H, G4, UpdateSheet!$I:$I, J4, UpdateSheet!$G:$G, "<=" & D4)) * (UpdateSheet!$H:$H=G4) *(UpdateSheet!$I:$I=J4), 0))), "")) + (IFNA(IF(A4="", "", INDEX(UpdateSheet!$O:$O, MATCH(1, (UpdateSheet!$G:$G=MAXIFS(UpdateSheet!$G:$G, UpdateSheet!$M:$M, K4,UpdateSheet!$N:$N, N4, UpdateSheet!$G:$G, "<=" & D4)) * (UpdateSheet!$M:$M=K4) *(UpdateSheet!$N:$N=N4), 0))), "")) )} -> 41500 | R4: {=IF(Q4:Q1891="","",Q4:Q1891-(O4:O1891+P4:P1891))} -> 29500 | S4: =if(A4="","","Pending") -> Pending | U4: {=IF(T4:T1891 = "", "",TEXT(T4:T1891,"mmmm"))} | V4: {=IF(T4:T1891 = "", "",TEXT(T4:T1891,"yyyy"))} | W4: =if(T4<>"",TRUE,FALSE) -> FALSE | Y4: call on Friday / not picking | Z4: New Order for Smart Tablets
A5: Felix Igene | B5: 9063651135 | C5: Edo | D5: 45880.766 | E5: August | F5: 2025 | G5: Smart Tablet | H5: 2 | J5: 2 | O5: {=IF(A5="", "", (IFNA(IF(A5="", "", INDEX(UpdateSheet!$L:$L, MATCH(1, (UpdateSheet!$G:$G=MAXIFS(UpdateSheet!$G:$G, UpdateSheet!$H:$H, G5, UpdateSheet!$G:$G, "<=" & D5)) * (UpdateSheet!$H:$H=G5), 0))), "") * J5) + (IFNA(IF(A5="", "", INDEX(UpdateSheet!$P:$P, MATCH(1, (UpdateSheet!$G:$G=MAXIFS(UpdateSheet!$G:$G, UpdateSheet!$M:$M, K5, UpdateSheet!$G:$G, "<=" & D5)) * (UpdateSheet!$M:$M=K5), 0))), "") * N5) )} -> 24000 | Q5: {=IF(A5="", "", (IFNA(IF(A5="", "", INDEX(UpdateSheet!$K:$K, MATCH(1, (UpdateSheet!$G:$G=MAXIFS(UpdateSheet!$G:$G, UpdateSheet!$H:$H, G5, UpdateSheet!$I:$I, J5, UpdateSheet!$G:$G, "<=" & D5)) * (UpdateSheet!$H:$H=G5) *(UpdateSheet!$I:$I=J5), 0))), "")) + (IFNA(IF(A5="", "", INDEX(UpdateSheet!$O:$O, MATCH(1, (UpdateSheet!$G:$G=MAXIFS(UpdateSheet!$G:$G, UpdateSheet!$M:$M, K5,UpdateSheet!$N:$N, N5, UpdateSheet!$G:$G, "<=" & D5)) * (UpdateSheet!$M:$M=K5) *(UpdateSheet!$N:$N=N5), 0))), "")) )} -> 65500 | R5: 41500 | S5: =if(A5="","","Pending") -> Pending | W5: =if(T5<>"",TRUE,FALSE) -> FALSE | Y5: still not picking | Z5: New Order for Smart Tablets
A6: Ojima Agonoh | B6: 8140771333 | C6: Ogun | D6: 45880.834 | E6: August | F6: 2025 | G6: Smart Tablet | H6: 1 | J6: 1 | O6: {=IF(A6="", "", (IFNA(IF(A6="", "", INDEX(UpdateSheet!$L:$L, MATCH(1, (UpdateSheet!$G:$G=MAXIFS(UpdateSheet!$G:$G, UpdateSheet!$H:$H, G6, UpdateSheet!$G:$G, "<=" & D6)) * (UpdateSheet!$H:$H=G6), 0))), "") * J6) + (IFNA(IF(A6="", "", INDEX(UpdateSheet!$P:$P, MATCH(1, (UpdateSheet!$G:$G=MAXIFS(UpdateSheet!$G:$G, UpdateSheet!$M:$M, K6, UpdateSheet!$G:$G, "<=" & D6)) * (UpdateSheet!$M:$M=K6), 0))), "") * N6) )} -> 12000 | Q6: {=IF(A6="", "", (IFNA(IF(A6="", "", INDEX(UpdateSheet!$K:$K, MATCH(1, (UpdateSheet!$G:$G=MAXIFS(UpdateSheet!$G:$G, UpdateSheet!$H:$H, G6, UpdateSheet!$I:$I, J6, UpdateSheet!$G:$G, "<=" & D6)) * (UpdateSheet!$H:$H=G6) *(UpdateSheet!$I:$I=J6), 0))), "")) + (IFNA(IF(A6="", "", INDEX(UpdateSheet!$O:$O, MATCH(1, (UpdateSheet!$G:$G=MAXIFS(UpdateSheet!$G:$G, UpdateSheet!$M:$M, K6,UpdateSheet!$N:$N, N6, UpdateSheet!$G:$G, "<=" & D6)) * (UpdateSheet!$M:$M=K6) *(UpdateSheet!$N:$N=N6), 0))), "")) )} -> 41500 | R6: 29500 | S6: Delivered | T6: 45882 | U6: August | V6: 2025 | W6: =if(T6<>"",TRUE,FALSE) -> TRUE | X6: Aboyeji | Z6: New Order for Smart Tablets
A7: Olufemi Ayoola | B7: 7061392221 | C7: Lagos | D7: 45880.841 | E7: August | F7: 2025 | G7: Smart Tablet | H7: 1 | J7: 1 | O7: {=IF(A7="", "", (IFNA(IF(A7="", "", INDEX(UpdateSheet!$L:$L, MATCH(1, (UpdateSheet!$G:$G=MAXIFS(UpdateSheet!$G:$G, UpdateSheet!$H:$H, G7, UpdateSheet!$G:$G, "<=" & D7)) * (UpdateSheet!$H:$H=G7), 0))), "") * J7) + (IFNA(IF(A7="", "", INDEX(UpdateSheet!$P:$P, MATCH(1, (UpdateSheet!$G:$G=MAXIFS(UpdateSheet!$G:$G, UpdateSheet!$M:$M, K7, UpdateSheet!$G:$G, "<=" & D7)) * (UpdateSheet!$M:$M=K7), 0))), "") * N7) )} -> 12000 | Q7: {=IF(A7="", "", (IFNA(IF(A7="", "", INDEX(UpdateSheet!$K:$K, MATCH(1, (UpdateSheet!$G:$G=MAXIFS(UpdateSheet!$G:$G, UpdateSheet!$H:$H, G7, UpdateSheet!$I:$I, J7, UpdateSheet!$G:$G, "<=" & D7)) * (UpdateSheet!$H:$H=G7) *(UpdateSheet!$I:$I=J7), 0))), "")) + (IFNA(IF(A7="", "", INDEX(UpdateSheet!$O:$O, MATCH(1, (UpdateSheet!$G:$G=MAXIFS(UpdateSheet!$G:$G, UpdateSheet!$M:$M, K7,UpdateSheet!$N:$N, N7, UpdateSheet!$G:$G, "<=" & D7)) * (UpdateSheet!$M:$M=K7) *(UpdateSheet!$N:$N=N7), 0))), "")) )} -> 41500 | R7: 29500 | S7: =if(A7="","","Pending") -> Pending | W7: =if(T7<>"",TRUE,FALSE) -> FALSE | Y7: not picking | Z7: New Order for Smart Tablets
A8: Favour Eguabor | B8: 8104989906 | C8: Edo | D8: 45880.916 | E8: August | F8: 2025 | G8: Smart Tablet | H8: 1 | J8: 1 | O8: {=IF(A8="", "", (IFNA(IF(A8="", "", INDEX(UpdateSheet!$L:$L, MATCH(1, (UpdateSheet!$G:$G=MAXIFS(UpdateSheet!$G:$G, UpdateSheet!$H:$H, G8, UpdateSheet!$G:$G, "<=" & D8)) * (UpdateSheet!$H:$H=G8), 0))), "") * J8) + (IFNA(IF(A8="", "", INDEX(UpdateSheet!$P:$P, MATCH(1, (UpdateSheet!$G:$G=MAXIFS(UpdateSheet!$G:$G, UpdateSheet!$M:$M, K8, UpdateSheet!$G:$G, "<=" & D8)) * (UpdateSheet!$M:$M=K8), 0))), "") * N8) )} -> 12000 | Q8: {=IF(A8="", "", (IFNA(IF(A8="", "", INDEX(UpdateSheet!$K:$K, MATCH(1, (UpdateSheet!$G:$G=MAXIFS(UpdateSheet!$G:$G, UpdateSheet!$H:$H, G8, UpdateSheet!$I:$I, J8, UpdateSheet!$G:$G, "<=" & D8)) * (UpdateSheet!$H:$H=G8) *(UpdateSheet!$I:$I=J8), 0))), "")) + (IFNA(IF(A8="", "", INDEX(UpdateSheet!$O:$O, MATCH(1, (UpdateSheet!$G:$G=MAXIFS(UpdateSheet!$G:$G, UpdateSheet!$M:$M, K8,UpdateSheet!$N:$N, N8, UpdateSheet!$G:$G, "<=" & D8)) * (UpdateSheet!$M:$M=K8) *(UpdateSheet!$N:$N=N8), 0))), "")) )} -> 41500 | R8: 29500 | S8: =if(A8="","","Pending") -> Pending | W8: =if(T8<>"",TRUE,FALSE) -> FALSE | Y8: to put it on hold for the mean time | Z8: New Order for Smart Tablets
A9: Christiana Akombu | B9: 8135530009 | C9: Benue | D9: 45882.05 | E9: August | F9: 2025 | G9: Smart Tablet | H9: 2 | J9: 2 | O9: {=IF(A9="", "", (IFNA(IF(A9="", "", INDEX(UpdateSheet!$L:$L, MATCH(1, (UpdateSheet!$G:$G=MAXIFS(UpdateSheet!$G:$G, UpdateSheet!$H:$H, G9, UpdateSheet!$G:$G, "<=" & D9)) * (UpdateSheet!$H:$H=G9), 0))), "") * J9) + (IFNA(IF(A9="", "", INDEX(UpdateSheet!$P:$P, MATCH(1, (UpdateSheet!$G:$G=MAXIFS(UpdateSheet!$G:$G, UpdateSheet!$M:$M, K9, UpdateSheet!$G:$G, "<=" & D9)) * (UpdateSheet!$M:$M=K9), 0))), "") * N9) )} -> 24000 | Q9: {=IF(A9="", "", (IFNA(IF(A9="", "", INDEX(UpdateSheet!$K:$K, MATCH(1, (UpdateSheet!$G:$G=MAXIFS(UpdateSheet!$G:$G, UpdateSheet!$H:$H, G9, UpdateSheet!$I:$I, J9, UpdateSheet!$G:$G, "<=" & D9)) * (UpdateSheet!$H:$H=G9) *(UpdateSheet!$I:$I=J9), 0))), "")) + (IFNA(IF(A9="", "", INDEX(UpdateSheet!$O:$O, MATCH(1, (UpdateSheet!$G:$G=MAXIFS(UpdateSheet!$G:$G, UpdateSheet!$M:$M, K9,UpdateSheet!$N:$N, N9, UpdateSheet!$G:$G, "<=" & D9)) * (UpdateSheet!$M:$M=K9) *(UpdateSheet!$N:$N=N9), 0))), "")) )} -> 65500 | R9: 41500 | S9: Cancelled | T9: 45882 | U9: August | V9: 2025 | W9: =if(T9<>"",TRUE,FALSE) -> TRUE | Y9: We don't send to Benue for now . | Z9: New Order for Smart Tablets
A10: ABDULAZIZ Mohammed | B10: 8037018058 | C10: Kano | D10: 45882.446 | E10: August | F10: 2025 | G10: Smart Tablet | H10: 1 | J10: 1 | O10: {=IF(A10="", "", (IFNA(IF(A10="", "", INDEX(UpdateSheet!$L:$L, MATCH(1, (UpdateSheet!$G:$G=MAXIFS(UpdateSheet!$G:$G, UpdateSheet!$H:$H, G10, UpdateSheet!$G:$G, "<=" & D10)) * (UpdateSheet!$H:$H=G10), 0))), "") * J10) + (IFNA(IF(A10="", "", INDEX(UpdateSheet!$P:$P, MATCH(1, (UpdateSheet!$G:$G=MAXIFS(UpdateSheet!$G:$G, UpdateSheet!$M:$M, K10, UpdateSheet!$G:$G, "<=" & D10)) * (UpdateSheet!$M:$M=K10), 0))), "") * N10) )} -> 12000 | Q10: {=IF(A10="", "", (IFNA(IF(A10="", "", INDEX(UpdateSheet!$K:$K, MATCH(1, (UpdateSheet!$G:$G=MAXIFS(UpdateSheet!$G:$G, UpdateSheet!$H:$H, G10, UpdateSheet!$I:$I, J10, UpdateSheet!$G:$G, "<=" & D10)) * (UpdateSheet!$H:$H=G10) *(UpdateSheet!$I:$I=J10), 0))), "")) + (IFNA(IF(A10="", "", INDEX(UpdateSheet!$O:$O, MATCH(1, (UpdateSheet!$G:$G=MAXIFS(UpdateSheet!$G:$G, UpdateSheet!$M:$M, K10,UpdateSheet!$N:$N, N10, UpdateSheet!$G:$G, "<=" & D10)) * (UpdateSheet!$M:$M=K10) *(UpdateSheet!$N:$N=N10), 0))), "")) )} -> 41500 | R10: 29500 | S10: =if(A10="","","Pending") -> Pending | W10: =if(T10<>"",TRUE,FALSE) -> FALSE | Y10: not picking | Z10: New Order for Smart Tablets
A11: Hebrew Emmanuel | B11: 8035885309 | C11: Abuja | D11: 45882.464 | E11: August | F11: 2025 | G11: Smart Tablet | H11: 1 | J11: 1 | O11: {=IF(A11="", "", (IFNA(IF(A11="", "", INDEX(UpdateSheet!$L:$L, MATCH(1, (UpdateSheet!$G:$G=MAXIFS(UpdateSheet!$G:$G, UpdateSheet!$H:$H, G11, UpdateSheet!$G:$G, "<=" & D11)) * (UpdateSheet!$H:$H=G11), 0))), "") * J11) + (IFNA(IF(A11="", "", INDEX(UpdateSheet!$P:$P, MATCH(1, (UpdateSheet!$G:$G=MAXIFS(UpdateSheet!$G:$G, UpdateSheet!$M:$M, K11, UpdateSheet!$G:$G, "<=" & D11)) * (UpdateSheet!$M:$M=K11), 0))), "") * N11) )} -> 12000 | Q11: {=IF(A11="", "", (IFNA(IF(A11="", "", INDEX(UpdateSheet!$K:$K, MATCH(1, (UpdateSheet!$G:$G=MAXIFS(UpdateSheet!$G:$G, UpdateSheet!$H:$H, G11, UpdateSheet!$I:$I, J11, UpdateSheet!$G:$G, "<=" & D11)) * (UpdateSheet!$H:$H=G11) *(UpdateSheet!$I:$I=J11), 0))), "")) + (IFNA(IF(A11="", "", INDEX(UpdateSheet!$O:$O, MATCH(1, (UpdateSheet!$G:$G=MAXIFS(UpdateSheet!$G:$G, UpdateSheet!$M:$M, K11,UpdateSheet!$N:$N, N11, UpdateSheet!$G:$G, "<=" & D11)) * (UpdateSheet!$M:$M=K11) *(UpdateSheet!$N:$N=N11), 0))), "")) )} -> 41500 | R11: 29500 | S11: =if(A11="","","Pending") -> Pending | W11: =if(T11<>"",TRUE,FALSE) -> FALSE | Y11: not reachable / not picking and not replying to text message | Z11: New Order for Smart Tablets
